Workbook

Sheet CoverSheet
C2: Approval of cloud applications Approval Date: 13.05.2023 Doc. Ref.: D PO 00-0068
B4: Selection and qualification of cloud service providers
B7: Guidance for completing this Questionnaire
B9: Please complete the “Cloud Service Provider Information” section on this page.
B10: Please answer only required questions based on Cloud type (IaaS, PaaS or SaaS) defined in columns "C" and "D"
B11: Please answer every question on"Questions" Tab with Yes, No, or N/A.
B12: When you answer with N/A, please add a commentary why this question does not apply in "CSP comment"
B13: When you cannot provide a response, please add a commentary with a short explanation.
B14: The regulated company is accountable for the regulated data, regardless of the service model (IaaS, PaaS, SaaS) or type of cloud
B15: de-ployment (public, hybrid, private).
B16: The responsibilities for data / endpoints / account / access management remain with the regulated company.
B17: This is the core of the enclosed cloud service provider questionnaire, which can be used based on service model.
B19: We are happy to arrange for a meeting to discuss questions and give you the opportunity to provide further details on your cloud offering and the controls you have in place.
... B25: General Information on the Cloud Service:
B26: Name of the Cloud Service Provider (CSP) / Application: | C26: Chemical.AI / ChemAIRS
B27: In what region/country is the application hosted: | C27: US (AWS; us-west-1)
B28: Is the Cloud Service Provider (CPS) subject to US laws: | C28: Yes
B30: Data Classification *To be completed by Siegfried Owner
B31: Data Classification:
B32: Service Model:
B33: Cloud Type:
B35: Cloud Service Provider Approval
B37: CISO Assessment:
B38: Decision CISO: ☐ Approved / ☐ Approved with obligation / ☐ Clarification required / ☐ Rejected
B39: Date:
B40: Comment CISO:
B43: CISO approval:
B49: This questionnaire was last updated in May 2023.

Sheet Questions
B2: Questionaire | G2: Cloud Service Provider | K2: CISO
B3: Requirement | C3: IaaS / PaaS | D3: SaaS | E3: Description | F3: Questions | G3: Yes | H3: No | I3: N/A | J3: CSP comment | K3: Risk detected | L3: CISO Acceptance | M3: CISO Comment
B4: 1. Compliance | G4: =COUNTA(G5:G18) -> 13 | H4: =COUNTA(H5:H18) -> 1 | I4: =COUNTA(I5:I18) -> 0
B5: Quality agreement | C5: Y (private cloud) N (public / hybrid) | D5: Y (private cloud) N (public / hybrid) | E5: The respective responsibilities of the regulated company and the CSP are described in a quality agreement | F5: Have all relevant activities and responsibilities been covered in a quality agreement? | G5: X | K5: =IF(ISBLANK(G5),"Yes","No") -> No
B6: Service Level agreement | C6: Y | D6: Y | E6: Service Level Agreements between the regulated company and the CSP specify the service level objectives, metrics, and targets that will be used to measure the performance of the service provider. | F6: Have all relevant activities and responsibilities been covered in a service level agreement? | G6: X | K6: =IF(ISBLANK(G6),"Yes","No") -> No
B7: Confirmation of compliance | C7: N | D7: Y | E7: The CSP must confirm in writing how the relevant data protection regulatory and legal requirements (e.g. DSG [Data Privacy Act] in Switzerland, GDPR in Europe), both at an organizational and technical level will be met. CSP shall put in place a mechanism whereby the Customer shall be notified of any changes | F7: Have all relevant regulato-ry and legal requirements, in particular with regard to data protection (e.g. DSG in Switzerland, GDPR in Europe), been implement-ed both at an organiza-tional and technical level? e.g. EU Cloud code of Conduct | G7: X | K7: =IF(ISBLANK(G7),"Yes","No") -> No
B8: Independent audits | C8: Y | D8: Y | E8: CSP shall provide the Customer, if available, an executive summary of independent third party audits and the certification of the CSP’s compliance with its obligations. CSP shall put in place a mechanism whereby the Customer shall be notified of negative findings | F8: Are independent audits performed on a regular basis to demonstrate that the cloud environment meets state-of-the-art/industry-best-practice requirements? | G8: X | K8: =IF(ISBLANK(G8),"Yes","No") -> No
F9: Were any deficiencies discovered during the last audit? Please provide evidence of the action plan to address these deficiencies. | H9: X | K9: =IF(ISBLANK(H9),"Yes","No") -> No
B10: Certifications | C10: Y | D10: Y | E10: CSP shall provide the Customer with any certificates, attestations or reports resulting from independent accredited third party audits of the Cloud Services. The CSP shall cooperate in good faith, in particular to enable adequate and timely responses. | F10: Are certifications such as ISAE-3402, SOC Type, ISO-27001, ISO-27017 or ISO-27018 in place to demonstrate that recognized standards have been implemented both at an organizational and technical level? | G10: X | K10: =IF(ISBLANK(G10),"Yes","No") -> No
B11: Continuous security review | C11: Y | D11: Y | E11: The CSP shall apply appropriate information security measures according to the sensitivity of the Customer (Personal) data contained within the cloud service. The CSP must prove that it continuously checks or has a third party check the cloud environment for vulnerabilities (e.g. internal audits, regular vulnerability scanning, penetration test, red teaming). The CSP shall take all appropriate steps to ensure the information security is a central part of any new developments to the relevant cloud service offerings. | F11: Is the cloud environment continuously checked for vulnerabilities (e.g. internal audits, regular vulnerability scanning, penetration test, red teaming)? Please provide evidence of the last vulnerability check. | G11: X | K11: =IF(ISBLANK(G11),"Yes","No") -> No
B12: Risk management | C12: Y | D12: Y | E12: The CSP shall establish, implement, maintain and continually improve an information security management system (ISMS), in accordance with the requirements of ISO 27001 or any equivalent International Standards The scope must include the organizational units, locations and procedures of the cloud provider for the provision of the cloud service. | F12: Is an information security management system (ISMS) operated according to a recognized standard (e.g. ISO/IEC 27001) and does the scope include the organizational units, locations and procedures for providing the cloud service? | G12: X | K12: =IF(ISBLANK(G12),"Yes","No") -> No
B13: Right to audit | C13: Y (private cloud) N (public / hybrid) | D13: Y (private cloud) N (public / hybrid) | E13: If the Customer requests further information, only the Customer or its mandated auditor may conduct an onsite visit of the CSP facilities used to provide the Cloud Service, provided that the Customer and, where applicable, the mandated auditor have signed an appropriate confidentiality agreement. | F13: Can Siegfried AG or a recognized company/organization commissioned by Siegfried AG be granted the "right to audit"? | G13: X | K13: =IF(ISBLANK(G13),"Yes","No") -> No
B14: Confidentiality requirements of the Cloud Strategy | C14: Y (private: C2 & C3) (public / hybrid: C0 & C1) | D14: Y (private: C2 & C3) (public / hybrid: C0 & C1) | E14: CSP shall have documented procedures to sufficiently communicate to the Customer the technical and organizational confidentiality measures implemented by the CSP prior to engaging in such data processing activi-ties. The confidentiality requirements are set out in the Cloud Strategy: - C0 Public: Encrypted transport of data - C1 Internal: Encrypted transport of data, secure and traceable deletion of data - C2 Confidential: Encrypted transport and storage of data, secure and traceable deletion of data - C3 Strictly confidential: In addition to C2, further security measures must be reviewed (e.g. location of the data center in Switzerland or the EU, secured data center connection). | F14: Can the confidentiality requirements set out in the Cloud Strategy be implemented? - C1 Internal: Encrypted transport of data, secure and traceable deletion of data - C2 Confidential: Encrypted transport and storage of data, secure and traceable deletion of data - C3 Strictly confidential: In addition to C2, further security measures must be reviewed (e.g. location of the data center in Switzerland or the European Union, secured data center connection). Note: C3 Strictly Confidential requires an exception approval. | G14: X | K14: =IF(ISBLANK(G14),"Yes","No") -> No
B15: Integrity requirements of the Cloud Strategy | C15: Y (private cloud: I1) (public / hybrid cloud: I0) | D15: Y (pri-vate cloud: I1) (pub-lic / hybrid cloud: I0) | E15: CSP shall have documented procedures to sufficiently communicate to the Customer the technical and organizational integrity measures implemented by the CSP prior to engaging in such data processing activities. The integrity requirements are set out in the Cloud Strategy : - I0 Basis: Detection of integrity violations using checksums, hash functions or certificates - I1 Extended: Encrypted transport and storage of data, logging of all data changes. | F15: Can the integrity requirements set out in the Cloud Strategy be implemented? - I0 Basis: Detection of integrity violations using checksums, hash functions or certificates - I1 Extended: Encrypted transport and storage of data, logging of all data changes. | G15: X | K15: =IF(ISBLANK(G15),"Yes","No") -> No
B16: Availability requirements of the Cloud Strategy | C16: Y (private and public / hybrid: V1 to V4) | D16: Y (private and public / hybrid: V1 to V4) | E16: CSP shall have documented procedures to sufficiently communicate to the Customer the technical and organizational availability measures implemented by the CSP prior to engaging in such data processing activi-ties. The availability requirements are set out in the Cloud Strategy : - V1 Low: Backup of data, applications and configurations - V2 Medium: Guaranteed availability ac-cording to defined SLA - V3 High: high availability (>99%), guaranteed SLA in case of disaster, redundant Internet connec-tion, highly available internal network. Note: for V4 Critical, two CSPs must be evaluated, both supporting C3 High. | F16: Can the availability requirements from the Cloud Strategy be implemented? - V1 Low: Backup of data, applications and configurations - V2 Medium: Guaranteed availability according to defined SLA - V3 High: high availability (>99%), guaranteed SLA in case of disaster, redundant Internet connection, highly available internal network. Note: for V4 Critical, two CSPs must be evaluated, both supporting V3 High. | G16: X | K16: =IF(ISBLANK(G16),"Yes","No") -> No
B17: Archiving requirements of the Cloud Strategy | C17: Y (private: A1) (public / hybrid: A0) | D17: Y (private: A1) (public / hybrid: A0) | E17: CSP shall have documented procedures to sufficiently communicate to the Customer the technical and organizational archiving measures implemented by the CSP prior to engaging in such data processing activi-ties. The archiving requirements are set out in the Cloud Strategy: - A0 No archiving: No measures - A1 Archiving: Storage in suitable for-mat, traceability guaranteed in the event of changes, periodic checking of archived data | F17: Can the archiving requirements from the Cloud Strategy be implemented? - A0 No archiving: No measures - A1 Archiving: Storage in suitable format, traceability guaranteed in the event of changes, periodic checking of archived data | G17: X | K17: =IF(ISBLANK(G17),"Yes","No") -> No
B18: Data privacy requirements of the Cloud Strategy | C18: Y (private cloud: P1/P2) (public / hybrid cloud: P0) | D18: Y (private cloud: P1/P2) (public / hybrid cloud: P0) | E18: CSP shall have documented procedures to sufficiently communicate to the Customer the technical and or-ganizational data privacy measures implemented by the CSP prior to engaging in such data processing activi-ties. The data privacy requirements are set out in the Cloud Strategy P0 no per-sonal data: no additional measures - P1 personal data: confidentiality requirements for C2 - P2 personal data requiring special pro-tection: confidentiality requirements for C3, further security measures must also be reviewed (e.g. lo-cation of the data center in Switzerland or the EU, secured data center connec-tion). | F18: Can the data privacy requirements from the Cloud Strategy be implemented? - P0 no personal data: no additional measures - P1 personal data: confidentiality requirements for C2 - P2 personal data requiring special protection: confidentiality requirements for C3, further security measures must also be reviewed (e.g. location of the data center in Switzerland or the European Union, secured data center connection). | G18: X | K18: =IF(ISBLANK(G18),"Yes","No") -> No
B19: 2. Data security | G19: =COUNTA(G20:G31) -> 8 | H19: =COUNTA(H20:H31) -> 4 | I19: =COUNTA(I20:I31) -> 0
B20: Identity management | C20: Y | D20: Y | E20: The CSP shall limit access to Customer (Personal) Data, both in the cloud and the facilities in which the Customer (Personal) Data is processed, including through logical access controls. The customer has to be able to autonomously manage the identities of users, and can delegate this to the CSP if no interfaces that support Identity Federation exists. | F20: Is it possible for Siegfried AG to autonomously manage the identities of users on behalf of the tenant? | H20: X | J20: Not fully autonomous in the standard SaaS model. With Azure AD SSO, Siegfried manages authentication/identities in its own IdP, and the ChemAIRS tenant administrator can reset passwords and manage roles/permissions (RBAC) within the tenant. However, user records must be pre-created on the ChemAIRS side — account creation is vendor-assisted on request (no SCIM auto-provisioning) and user removal is request-based (~1–3 weeks). Automated/self-service provisioning (SCIM) can be evaluated case-by-case. | K20: =IF(ISBLANK(G20),"Yes","") -> Yes
F21: Can interfaces be provided that support Identity Federation? | G21: X | K21: =IF(ISBLANK(G21),"Yes","")
B22: Permission management | C22: Y | D22: Y | E22: The CSP must have a policy that governs procedures for access and access permissions. The following items in particular must be covered: - Modification, suspension, and revocation of access and access permissions for internal and external employees - Support for role-based access (RBAC) - Regular checking of permissions - Handling of privileged personal and technical accounts | F22: Is there a policy that specifies regulated procedures for access and access permissions, and are the following points covered in particular? - Modification, suspension, and revocation of access and access permissions for internal and external employees - Support for role-based access (RBAC) - Regular checking of permissions - Handling of privileged personal and technical accounts | G22: X | K22: =IF(ISBLANK(G22),"Yes","")
B23: Authentication and access procedures | C23: Y | D23: Y | E23: The CSP must provide two-factor authentication (mobile TAN is to be avoided if possible) for the following cases as a minimum: - Cloud services includes data/information classified as 'customer data', 'employee data', and all non-public 'business information' - For users with privileges and permissions (e.g. administrators) - For users with permissions of a changing nature (e.g. HelpDesk, Support) If the cloud services are accessed from a secured company network via a VPN, for which two-factor authentication was already required, then in this case renewed two-factor authentication can be dispensed with. To increase security, access to the services should be restricted, If possible, to specific IP addresses or domains | F23: Is two-factor authentication (mobile TAN is to be avoided if possible) guaranteed in the following cases: - Cloud services includes data/information classified as 'customer data', 'employee data', and all non-public 'business information'. - For users with privileges and permissions (e.g. administrators) - For users with permissions of a changing nature (e.g. HelpDesk, Support) If the cloud services are accessed from a secured company network via a VPN, for which two-factor authentication was already required, then in this case renewed two-factor authentication can be dispensed with. | G23: X | K23: =IF(ISBLANK(G23),"Yes","")
F24: Is it guaranteed that access to the services is restricted to specific IP addresses or domains? | H24: X | J24: Customer-configurable source-IP / domain allowlisting for tenant access is not available in the standard SaaS environment. Network-layer protections do exist (AWS WAF, anti-DDoS, internal-only VPC/ClusterIP with no public exposure beyond the web frontend, and database access restricted to specific IP ranges), but these are provider-managed and not a customer-defined IP restriction. IP-based access restriction can be evaluated for local/dedicated deployments. | K24: =IF(ISBLANK(G24),"Yes","") -> Yes
B25: Cryptography / Encryption Key management | C25: Y | D25: Y | E25: Where technically feasible and operationally practicable, the CSP shall make available and/or implement encryption controls – at least for any transit of data – to protect the confidentiality of Customer (Personal) data in the cloud. The CSP must use state-of-the-art encryption methods, and use them on a risk-based basis. It must enable Siegfried AG to create and manage codes itself, and have defined requirements for the secure generation, storage, archiving, retrieval, distribution, revocation and deletion of codes. CSP shall put in place a mechanism whereby the Customer shall be notified of changes | F25: Are encryption methods used that reflect state-of-the-art technology and are these used on a risk-based basis? | G25: X | K25: =IF(ISBLANK(G25),"Yes","")
F26: Is it possible for Siegfried AG to create and manage the encryption keys itself and are the encryption principles of Siegfried AG adhered to? | H26: X | J26: In multi-tenant SaaS, encryption keys are generated and managed by ChemAIRS/AWS (KMS). Customer-managed keys (BYOK) are not offered in SaaS. Local deployment gives the customer full control over keys and its own key-management principles. | K26: =IF(ISBLANK(G26),"Yes","") -> Yes
F27: Are requirements defined for the secure generation, storage, archiving, retrieval, distribution, revocation, and deletion of encryption keys? | G27: X | K27: =IF(ISBLANK(G27),"Yes","")
B28: Decommissioning | C28: Y | D28: Y | E28: The CSP must support the complete and irrevocable deletion of data or the proper destruction of hardware and data media (including backup media) (e.g., through "crypto-shredding"). | F28: Is the complete and irrevocable deletion of data or the proper destruction of hardware and data media (including backup media) supported (e.g., through "crypto-shredding")? | G28: X | K28: =IF(ISBLANK(G28),"Yes","")
B29: DLP/IRM (DRM) | C29: Y | D29: Y | E29: The CSP must offer a Data Loss Prevention (DLP) and Information Rights Management (IRM) solution integrated into its cloud platform, which Siegfried AG can configure according to its needs.Alternatively, the CSP must enable Siegfried AG to use third-party solutions for DLP and IRM. CSP shall put in place a mechanism whereby the Customer shall be notified of changes | F29: Is a Data Loss Prevention (DLP) and Information Rights Management (IRM) solution integrated in the cloud platform, and can it be configured by Siegfried AG according to its needs? | H29: X | J29: No dedicated DLP or IRM/DRM solution is integrated into the ChemAIRS platform for customer configuration. In-platform data protection is provided through data classification (Public/Internal/Sensitive/Confidential), RBAC and least-privilege access, tenant isolation, encryption at rest/in transit, and audit logging with log export/deletion controls. Endpoint controls (USB/clipboard/screenshot/file-transfer monitoring) exist on Chemical.AI's own workstations but are internal and not customer-configurable. For local deployment, data remains entirely within the customer's environment, allowing Siegfried to apply its own DLP/IRM controls. | K29: =IF(ISBLANK(G29),"Yes","") -> Yes
F30: Alternatively, can third-party solutions for DLP and IRM be integrated into the cloud platform? | G30: X | K30: =IF(ISBLANK(G30),"Yes","")
B31: Data backup and recovery | C31: Y | D31: Y | E31: The CSP shall adopt physi-cal and logical measures, designed to prevent data loss and unauthorized ac-cess, alteration to or de-struction of the information processing facilities. The CSP must have a concept for regular data backup and data recovery that covers the following points in particular: - adequate protection of backed up data - monitoring of data backup - testing of recovery procedures CSP shall put in place a mechanism whereby the Customer shall be notified of changes | F31: Does a concept for regular data backup and data recovery exist that covers the following points in particular: - adequate protection of backed up data - monitoring of data backup - testing of recovery procedures | G31: X | K31: =IF(ISBLANK(G31),"Yes","")
B32: 3. IT regular operation | G32: =COUNTA(G33:G43) -> 11 | H32: =COUNTA(H33:H43) -> 0 | I32: =COUNTA(I33:I43) -> 0
B33: Asset management | C33: Y (private cloud) N (public cloud) | D33: Y (private cloud) N (public cloud) | E33: The CSP must provide Siegfried AG with an inventory of IT assets, showing the respective status of assets (active, inactive, planned, etc.). The CSP must have procedures for the orderly commissioning, decommissioning and management of IT assets. | F33: Does an asset inventory exist that shows the respective status of assets (active, inactive, planned, etc.)? Please provide evidence of the asset inventory. | G33: X | K33: =IF(ISBLANK(G33),"Yes","No") -> No
F34: Are there procedures for the orderly commissioning, decommissioning and management of assets? | G34: X | K34: =IF(ISBLANK(G34),"Yes","No") -> No
B35: Availability management | C35: Y | D35: Y | E35: The CSP must establish monitoring services and demonstrate the system availability provided by the CSP The CSP must have an established procedure for monitoring and controlling the availability of the sys-tems it provides. | F35: Is an established procedure used for monitoring and controlling the availability of the systems provided? | G35: X | K35: =IF(ISBLANK(G35),"Yes","No") -> No
B36: Capacity management | C36: Y | D36: Y | E36: The CSP must have an established procedure for planning, monitoring and controlling capacities and resources (personnel and IT resources). | F36: Is an established procedure for planning, monitoring and controlling capacities and resources (personnel and IT resources) in place? | G36: X | K36: =IF(ISBLANK(G36),"Yes","No") -> No
B37: Change management | C37: Y | D37: Y | E37: The CSP must have an established procedure for planning, risk assessment, testing, approval and implementation of changes (including major changes such as new releases). The CSP must incorporate the frozen zones and maintenance windows defined by Siegfried AG. CSP shall put in place a mechanism whereby the Customer shall be notified of changes. | F37: Is an established process used for planning, risk assessment, testing, approval, and implementation of changes (including major changes such as new releases)? | G37: X | K37: =IF(ISBLANK(G37),"Yes","No") -> No
F38: Can the frozen zones and maintenance windows defined by Siegfried AG be incorporated individually? | G38: X | K38: =IF(ISBLANK(G38),"Yes","No") -> No
B39: Configuration management | C39: Y | D39: Y | E39: The CSP must have an established procedure for the definition, application and conformity control of standardized and secure configurations. | F39: Is an established procedure used for the definition, application and conformance control of standardized and secure configurations? | G39: X | K39: =IF(ISBLANK(G39),"Yes","No") -> No
B40: Vulnerability management | C40: Y | D40: Y | E40: The CSP must have a concept for dealing with vulnerabilities that describes both technical and organizational measures, in particular with regard to: - Regular identification of vulnerabilities - Documentation and assessment of vulnerabilities - Definition and implementation of prioritized measures to eliminate vulnerabilities - Reporting including trends Including an effective re-sponse to the Customer, about any (potential) vulner-abilities | F40: Does a concept exist for dealing with vulnerabilities that describes both the technical and organizational measures, particularly with regard to: - Regular identification of vulnerabilities - Documentation and assessment of vulnerabilities - Definition and implementation of prioritized measures to eliminate vulnerabilities - Reporting including trends | G40: X | K40: =IF(ISBLANK(G40),"Yes","No") -> No
B41: Incident management | C41: Y | D41: Y | E41: The CSP shall develop, im-plement and manage poli-cies and procedures ena-bling an effective response to and (where legally re-quired) communication to the Customer, data subjects or competent authorities in relation to (personal) data breaches.. These must de-scribe technical as well as organizational measures, in particular regarding: - Criteria for classification, prioritization and escalation - Consideration of regulatory requirements - Involvement of Siegfried AG in the remediation process - Documentation and reporting - Securing evidence (for forensic analysis) | F41: Do guidelines and instructions exist to ensure a fast, effective and proper response to (security) incidents, describing technical as well as organizational measures, in particular regarding: - Criteria for classification, prioritization and escalation - Consideration of regulatory requirements - Involvement of Siegfried AG in the remediation process - Documentation and reporting - Securing evidence (for forensic analysis) | G41: X | K41: =IF(ISBLANK(G41),"Yes","No") -> No
...

Sheet Glossary
B2: C5 | C2: Cloud computing compliance criteria catalogue:
B3: Cloud computing | C3: paradigm for enabling network access to a scalable and elastic pool of shareable physical or virtual resources with self-service provisioning and administration on demand provided by a CSP
B4: CSP | C4: ‘Cloud Service Provider’: party which processes personal data in its capacity as a Processor.
B5: Customer | C5: party which is in a business relationship with a CSP for the purpose of using Cloud Services, either being a processor itself or the controller
B6: CSA | C6: Cloud Services Agreement: the full (set of) written agreements between the CSP and the Customer, which includes their contractual obligations, including with respect to a legally binding data processing agreement. A Cloud Services Agreement shall be in place between the CSP and the Customer, incorporating the data protection obligations under GDPR as a minimum.
B7: Cloud services | C7: One or more capabilities offered via Cloud Computing invoked using a defined interface, including but not limited to IaaS, SaaS, PaaS.
B8: Customer (personal) data | C8: Any personal data in relation to data subjects that the Customer entrusts to the CSP as part of the provision of the Cloud Services
B9: Data protection | C9: Describes the substantive rights and obligations of adhering CSPs on the basis of key principles, for instance purpose delimitations, data transfers, security, auditing, liability, data subject rights
B10: DLP | C10: Data Loss Prevention is a technology that blocks sensitive material from going outside the organization.
B11: IRM | C11: Information Rights Management is an encryption solution that maintain the encryption of the information regardless of where it is sent, and permissions to allow or deny users from taking certain actions on a piece of information.
B12: Information security | C12: Protection of the information the Cloud Service Provider’s customers processed, stored or transmitted in the cloud service with respect to the protection objectives of confidentiality, integrity, availability and authenticity.
B13: IaaS | C13: Infrastructure as a Service is a cloud computing service model by means of which "raw" computing resources are supplied by a cloud services provider. The IaaS vendor provides the storage, network, servers, and virtualization
... B21: RPO | C21: Recovery Point Objective is based on the amount of data that can be lost without causing irreparable damage to the business, essentially dictating the acceptable time interval between backups.

Sheet Standards
B2: Control | C2: Annex 11 computerized systems guidelines | D2: GDPR compliant | E2: ISO 27001 ISMS | F2: ISO 27017 Cloud data security | G2: ISO 27018 Protecting personal identifiable data in the cloud | H2: ISO 27701 Privacy information management | I2: ISAE SOC type2 | J2: C5:2020 cloud computing compliance criteria catalogue | K2: NIST SP 800-53 US security and privacy controls | L2: NIST Cybersecurity framework CSF 2.0
B3: 1.compliance
B4: 2.data security
B5: 3.IT regular operation
B6: 4.IT security monitoring
B7: 5. Infrastructure security
B8: 6. Safety of personnel
B9: 7. Application security
B10: 8.Contractual and commercial aspects

Sheet Assessment
C1: Current | D1: Target | E1: No | F1: N/A
B2: =Questions!B4 -> 1. Compliance | C2: =Questions!G4 -> 13 | D2: 14 | E2: =Questions!H4 -> 1 | F2: =Questions!I4 -> 0
B3: =Questions!B19 -> 2. Data security | C3: =Questions!G19 -> 8 | D3: 12 | E3: =Questions!H19 -> 4 | F3: =Questions!I19 -> 0
B4: =Questions!B32 -> 3. IT regular operation | C4: =Questions!G32 -> 11 | D4: 11 | E4: =Questions!H32 -> 0 | F4: =Questions!I32 -> 0
B5: =Questions!B44 -> 4. IT security monitoring | C5: =Questions!G44 -> 4 | D5: 5 | E5: =Questions!H44 -> 1 | F5: =Questions!I44 -> 0
B6: =Questions!B50 -> 5. Infrastructure security | C6: =Questions!G50 -> 5 | D6: 5 | E6: =Questions!H50 -> 0 | F6: =Questions!I50 -> 0
B7: =Questions!B56 -> 6. Safety of personnel | C7: =Questions!G56 -> 3 | D7: 3 | E7: =Questions!H56 -> 0 | F7: =Questions!I56 -> 0
B8: =Questions!B60 -> 7. Application security | C8: =Questions!G60 -> 2 | D8: 2 | E8: =Questions!H60 -> 0 | F8: =Questions!I60 -> 0
B9: =Questions!B63 -> 8. Contractual and commercial aspects | C9: =Questions!G63 -> 6 | D9: 6 | E9: =Questions!H63 -> 0 | F9: =Questions!I63 -> 0
